<?xml version="1.0" encoding="UTF-8"?>
<!-- Generated by org.testng.reporters.JUnitReportReporter -->
<testsuite hostname="DESKTOP-JPVJA3L" failures="2" tests="4" name="com.xyz.qa.Testcases.AddCustomerTest" time="35.099" errors="0" timestamp="07 Mar 2024 19:02:19 GMT" skipped="0">
  <testcase classname="com.xyz.qa.Testcases.AddCustomerTest" name="AddCustomerTitleTest" time="6.370"/>
  <testcase classname="com.xyz.qa.Testcases.AddCustomerTest" name="addcustomerwithInvalidData" time="8.985">
    <failure message="First name should not be added with invalid data expected [false] but found [true]" type="java.lang.AssertionError">
      <![CDATA[java.lang.AssertionError: First name should not be added with invalid data expected [false] but found [true]
	at org.testng.Assert.fail(Assert.java:93)
	at org.testng.Assert.failNotEquals(Assert.java:512)
	at org.testng.Assert.assertFalse(Assert.java:62)
	at com.xyz.qa.Testcases.AddCustomerTest.addcustomerwithInvalidData(AddCustomerTest.java:62)
	at java.base/jdk.internal.reflect.NativeMethodAccessorImpl.invoke0(Native Method)
	at java.base/jdk.internal.reflect.NativeMethodAccessorImpl.invoke(NativeMethodAccessorImpl.java:64)
	at java.base/jdk.internal.reflect.DelegatingMethodAccessorImpl.invoke(DelegatingMethodAccessorImpl.java:43)
	at java.base/java.lang.reflect.Method.invoke(Method.java:564)
	at org.testng.internal.MethodInvocationHelper.invokeMethod(MethodInvocationHelper.java:108)
	at org.testng.internal.Invoker.invokeMethod(Invoker.java:661)
	at org.testng.internal.Invoker.invokeTestMethod(Invoker.java:869)
	at org.testng.internal.Invoker.invokeTestMethods(Invoker.java:1193)
	at org.testng.internal.TestMethodWorker.invokeTestMethods(TestMethodWorker.java:126)
	at org.testng.internal.TestMethodWorker.run(TestMethodWorker.java:109)
	at org.testng.TestRunner.privateRun(TestRunner.java:744)
	at org.testng.TestRunner.run(TestRunner.java:602)
	at org.testng.SuiteRunner.runTest(SuiteRunner.java:380)
	at org.testng.SuiteRunner.access$000(SuiteRunner.java:39)
	at org.testng.SuiteRunner$SuiteWorker.run(SuiteRunner.java:414)
	at org.testng.internal.thread.ThreadUtil$1.call(ThreadUtil.java:52)
	at java.base/java.util.concurrent.FutureTask.run(FutureTask.java:264)
	at java.base/java.util.concurrent.ThreadPoolExecutor.runWorker(ThreadPoolExecutor.java:1130)
	at java.base/java.util.concurrent.ThreadPoolExecutor$Worker.run(ThreadPoolExecutor.java:630)
	at java.base/java.lang.Thread.run(Thread.java:832)
]]>
    </failure>
  </testcase> <!-- addcustomerwithInvalidData -->
  <testcase classname="com.xyz.qa.Testcases.AddCustomerTest" name="addcustomerwithvalidData" time="9.835"/>
  <testcase classname="com.xyz.qa.Testcases.AddCustomerTest" name="addcustomerwithblankData" time="9.909">
    <failure message="First name is not displayed expected [false] but found [true]" type="java.lang.AssertionError">
      <![CDATA[java.lang.AssertionError: First name is not displayed expected [false] but found [true]
	at org.testng.Assert.fail(Assert.java:93)
	at org.testng.Assert.failNotEquals(Assert.java:512)
	at org.testng.Assert.assertFalse(Assert.java:62)
	at com.xyz.qa.Testcases.AddCustomerTest.addcustomerwithblankData(AddCustomerTest.java:76)
	at java.base/jdk.internal.reflect.NativeMethodAccessorImpl.invoke0(Native Method)
	at java.base/jdk.internal.reflect.NativeMethodAccessorImpl.invoke(NativeMethodAccessorImpl.java:64)
	at java.base/jdk.internal.reflect.DelegatingMethodAccessorImpl.invoke(DelegatingMethodAccessorImpl.java:43)
	at java.base/java.lang.reflect.Method.invoke(Method.java:564)
	at org.testng.internal.MethodInvocationHelper.invokeMethod(MethodInvocationHelper.java:108)
	at org.testng.internal.Invoker.invokeMethod(Invoker.java:661)
	at org.testng.internal.Invoker.invokeTestMethod(Invoker.java:869)
	at org.testng.internal.Invoker.invokeTestMethods(Invoker.java:1193)
	at org.testng.internal.TestMethodWorker.invokeTestMethods(TestMethodWorker.java:126)
	at org.testng.internal.TestMethodWorker.run(TestMethodWorker.java:109)
	at org.testng.TestRunner.privateRun(TestRunner.java:744)
	at org.testng.TestRunner.run(TestRunner.java:602)
	at org.testng.SuiteRunner.runTest(SuiteRunner.java:380)
	at org.testng.SuiteRunner.access$000(SuiteRunner.java:39)
	at org.testng.SuiteRunner$SuiteWorker.run(SuiteRunner.java:414)
	at org.testng.internal.thread.ThreadUtil$1.call(ThreadUtil.java:52)
	at java.base/java.util.concurrent.FutureTask.run(FutureTask.java:264)
	at java.base/java.util.concurrent.ThreadPoolExecutor.runWorker(ThreadPoolExecutor.java:1130)
	at java.base/java.util.concurrent.ThreadPoolExecutor$Worker.run(ThreadPoolExecutor.java:630)
	at java.base/java.lang.Thread.run(Thread.java:832)
]]>
    </failure>
  </testcase> <!-- addcustomerwithblankData -->
</testsuite> <!-- com.xyz.qa.Testcases.AddCustomerTest -->
